[2024-10-16T14:06:39.670] [DEBUG] default - TypeError: this.build(...).save is not a function
    at Function.create (D:\Dev SIPPP\PMO\sidapet-be-reb\rebuild-sidapet-be\node_modules\sequelize\src\model.js:2311:8)
    at D:\Dev SIPPP\PMO\sidapet-be-reb\rebuild-sidapet-be\src\services\api\v1\profilVendor-service.ts:169:50
    at Generator.next (<anonymous>)
    at fulfilled (D:\Dev SIPPP\PMO\sidapet-be-reb\rebuild-sidapet-be\src\services\api\v1\profilVendor-service.ts:5:58)
    at processTicksAndRejections (node:internal/process/task_queues:95:5)
[2024-10-16T14:07:54.846] [DEBUG] default - Error
    at Query.run (D:\Dev SIPPP\PMO\sidapet-be-reb\rebuild-sidapet-be\node_modules\sequelize\src\dialects\postgres\query.js:76:25)
    at D:\Dev SIPPP\PMO\sidapet-be-reb\rebuild-sidapet-be\node_modules\sequelize\src\sequelize.js:650:28
    at processTicksAndRejections (node:internal/process/task_queues:95:5)
    at async PostgresQueryInterface.bulkInsert (D:\Dev SIPPP\PMO\sidapet-be-reb\rebuild-sidapet-be\node_modules\sequelize\src\dialects\abstract\query-interface.js:881:21)
    at async recursiveBulkCreate (D:\Dev SIPPP\PMO\sidapet-be-reb\rebuild-sidapet-be\node_modules\sequelize\src\model.js:2850:25)
    at async Function.bulkCreate (D:\Dev SIPPP\PMO\sidapet-be-reb\rebuild-sidapet-be\node_modules\sequelize\src\model.js:2976:12) {
  name: 'SequelizeDatabaseError',
  parent: error: null value in column "kode_jawab_profil" of relation "trx_jawab_profil" violates not-null constraint
      at Parser.parseErrorMessage (D:\Dev SIPPP\PMO\sidapet-be-reb\rebuild-sidapet-be\node_modules\pg-protocol\src\parser.ts:368:69)
      at Parser.handlePacket (D:\Dev SIPPP\PMO\sidapet-be-reb\rebuild-sidapet-be\node_modules\pg-protocol\src\parser.ts:187:21)
      at Parser.parse (D:\Dev SIPPP\PMO\sidapet-be-reb\rebuild-sidapet-be\node_modules\pg-protocol\src\parser.ts:102:30)
      at Socket.<anonymous> (D:\Dev SIPPP\PMO\sidapet-be-reb\rebuild-sidapet-be\node_modules\pg-protocol\src\index.ts:7:48)
      at Socket.emit (node:events:513:28)
      at Socket.emit (node:domain:489:12)
      at addChunk (node:internal/streams/readable:324:12)
      at readableAddChunk (node:internal/streams/readable:297:9)
      at Socket.Readable.push (node:internal/streams/readable:234:10)
      at TCP.onStreamRead (node:internal/stream_base_commons:190:23) {
    length: 254,
    severity: 'ERROR',
    code: '23502',
    detail: 'Baris gagal berisi (null, 19, 52, Tes Usaha)',
    hint: undefined,
    position: undefined,
    internalPosition: undefined,
    internalQuery: undefined,
    where: undefined,
    schema: 'public',
    table: 'trx_jawab_profil',
    column: 'kode_jawab_profil',
    dataType: undefined,
    constraint: undefined,
    file: 'execMain.c',
    line: '2009',
    routine: 'ExecConstraints',
    sql: `INSERT INTO "public"."trx_jawab_profil" ("kode_jawab_profil","kode_vendor","kode_item","isian") VALUES (NULL,19,52,'Tes Usaha'),(NULL,19,54,'Jl. Legoso') RETURNING "kode_jawab_profil","kode_vendor","kode_item","isian";`,
    parameters: undefined
  },
  original: error: null value in column "kode_jawab_profil" of relation "trx_jawab_profil" violates not-null constraint
      at Parser.parseErrorMessage (D:\Dev SIPPP\PMO\sidapet-be-reb\rebuild-sidapet-be\node_modules\pg-protocol\src\parser.ts:368:69)
      at Parser.handlePacket (D:\Dev SIPPP\PMO\sidapet-be-reb\rebuild-sidapet-be\node_modules\pg-protocol\src\parser.ts:187:21)
      at Parser.parse (D:\Dev SIPPP\PMO\sidapet-be-reb\rebuild-sidapet-be\node_modules\pg-protocol\src\parser.ts:102:30)
      at Socket.<anonymous> (D:\Dev SIPPP\PMO\sidapet-be-reb\rebuild-sidapet-be\node_modules\pg-protocol\src\index.ts:7:48)
      at Socket.emit (node:events:513:28)
      at Socket.emit (node:domain:489:12)
      at addChunk (node:internal/streams/readable:324:12)
      at readableAddChunk (node:internal/streams/readable:297:9)
      at Socket.Readable.push (node:internal/streams/readable:234:10)
      at TCP.onStreamRead (node:internal/stream_base_commons:190:23) {
    length: 254,
    severity: 'ERROR',
    code: '23502',
    detail: 'Baris gagal berisi (null, 19, 52, Tes Usaha)',
    hint: undefined,
    position: undefined,
    internalPosition: undefined,
    internalQuery: undefined,
    where: undefined,
    schema: 'public',
    table: 'trx_jawab_profil',
    column: 'kode_jawab_profil',
    dataType: undefined,
    constraint: undefined,
    file: 'execMain.c',
    line: '2009',
    routine: 'ExecConstraints',
    sql: `INSERT INTO "public"."trx_jawab_profil" ("kode_jawab_profil","kode_vendor","kode_item","isian") VALUES (NULL,19,52,'Tes Usaha'),(NULL,19,54,'Jl. Legoso') RETURNING "kode_jawab_profil","kode_vendor","kode_item","isian";`,
    parameters: undefined
  },
  sql: `INSERT INTO "public"."trx_jawab_profil" ("kode_jawab_profil","kode_vendor","kode_item","isian") VALUES (NULL,19,52,'Tes Usaha'),(NULL,19,54,'Jl. Legoso') RETURNING "kode_jawab_profil","kode_vendor","kode_item","isian";`,
  parameters: {}
}
[2024-10-16T15:25:40.554] [DEBUG] default - TypeError: Cannot read properties of undefined (reading 'path')
    at D:\Dev SIPPP\PMO\sidapet-be-reb\rebuild-sidapet-be\src\services\api\v1\vendorRegister-service.ts:166:56
    at Generator.next (<anonymous>)
    at fulfilled (D:\Dev SIPPP\PMO\sidapet-be-reb\rebuild-sidapet-be\src\services\api\v1\vendorRegister-service.ts:28:58)
    at processTicksAndRejections (node:internal/process/task_queues:95:5)
[2024-10-16T15:25:59.813] [DEBUG] default - Error: ModuleNotFoundError: No module named 'face_recognition'
    at PythonShell.parseError (D:\Dev SIPPP\PMO\sidapet-be-reb\rebuild-sidapet-be\node_modules\python-shell\index.ts:376:21)
    at terminateIfNeeded (D:\Dev SIPPP\PMO\sidapet-be-reb\rebuild-sidapet-be\node_modules\python-shell\index.ts:239:32)
    at ChildProcess.<anonymous> (D:\Dev SIPPP\PMO\sidapet-be-reb\rebuild-sidapet-be\node_modules\python-shell\index.ts:230:13)
    at ChildProcess.emit (node:events:513:28)
    at ChildProcess.emit (node:domain:489:12)
    at Process.ChildProcess._handle.onexit (node:internal/child_process:291:12)
    ----- Python Traceback -----
    File "D:\Dev SIPPP\PMO\sidapet-be-reb\rebuild-sidapet-be\src\python\facerecognitionpersonalid.py", line 1, in <module>
      import face_recognition {
  traceback: 'Traceback (most recent call last):\r\n' +
    '  File "D:\\Dev SIPPP\\PMO\\sidapet-be-reb\\rebuild-sidapet-be\\src\\python\\facerecognitionpersonalid.py", line 1, in <module>\r\n' +
    '    import face_recognition\r\n' +
    "ModuleNotFoundError: No module named 'face_recognition'\r\n",
  executable: 'python',
  options: null,
  script: 'src\\python\\facerecognitionpersonalid.py',
  args: [
    'D:\\Dev SIPPP\\PMO\\public\\sidapet\\images\\foto-ktp\\userphoto-1729067157898.png'
  ],
  exitCode: 1,
  logs: []
}
